2018-11-02 17-22-01 - Mobius Bot sent to channel bot_testing : Mobius Server system check: 0 | Traceback (most recent call last):
  File "C:\Users\mwyoo\Google Drive\Michael's Documents\Misc\Coding Projects\Mobius System\Mobius - Dev\Bot\Mobiusbot.py", line 127, in on_message
    msg2=fn.register(usrobj)
  File "C:\Users\mwyoo\Google Drive\Michael's Documents\Misc\Coding Projects\Mobius System\Mobius - Dev\Bot\functions.py", line 162, in register
    os.makedirs(userinfo["folder"])
  File "C:\Users\mwyoo\AppData\Local\Programs\Python\Python36-32\lib\os.py", line 220, in makedirs
    mkdir(name, mode)
FileExistsError: [WinError 183] Cannot create a file when that file already exists: './Mobius_Users/Mobius Bot4811_443058935784669194'

2018-11-02 17-22-01 - Mobius Bot sent to channel bot_testing : Mobius Startup complete | Traceback (most recent call last):
  File "C:\Users\mwyoo\Google Drive\Michael's Documents\Misc\Coding Projects\Mobius System\Mobius - Dev\Bot\Mobiusbot.py", line 127, in on_message
    msg2=fn.register(usrobj)
  File "C:\Users\mwyoo\Google Drive\Michael's Documents\Misc\Coding Projects\Mobius System\Mobius - Dev\Bot\functions.py", line 162, in register
    os.makedirs(userinfo["folder"])
  File "C:\Users\mwyoo\AppData\Local\Programs\Python\Python36-32\lib\os.py", line 220, in makedirs
    mkdir(name, mode)
FileExistsError: [WinError 183] Cannot create a file when that file already exists: './Mobius_Users/Mobius Bot4811_443058935784669194'

2018-11-02 17-22-02 - Mobius Bot sent to channel bot_testing : Error Caught On Command
Event has been logged and a notification has been sent. | Traceback (most recent call last):
  File "C:\Users\mwyoo\Google Drive\Michael's Documents\Misc\Coding Projects\Mobius System\Mobius - Dev\Bot\Mobiusbot.py", line 127, in on_message
    msg2=fn.register(usrobj)
  File "C:\Users\mwyoo\Google Drive\Michael's Documents\Misc\Coding Projects\Mobius System\Mobius - Dev\Bot\functions.py", line 162, in register
    os.makedirs(userinfo["folder"])
  File "C:\Users\mwyoo\AppData\Local\Programs\Python\Python36-32\lib\os.py", line 220, in makedirs
    mkdir(name, mode)
FileExistsError: [WinError 183] Cannot create a file when that file already exists: './Mobius_Users/Mobius Bot4811_443058935784669194'

2018-11-02 17-22-03 - Mobius Bot sent to channel bot_testing : Error Caught On Command | Traceback (most recent call last):
  File "C:\Users\mwyoo\Google Drive\Michael's Documents\Misc\Coding Projects\Mobius System\Mobius - Dev\Bot\Mobiusbot.py", line 127, in on_message
    msg2=fn.register(usrobj)
  File "C:\Users\mwyoo\Google Drive\Michael's Documents\Misc\Coding Projects\Mobius System\Mobius - Dev\Bot\functions.py", line 162, in register
    os.makedirs(userinfo["folder"])
  File "C:\Users\mwyoo\AppData\Local\Programs\Python\Python36-32\lib\os.py", line 220, in makedirs
    mkdir(name, mode)
FileExistsError: [WinError 183] Cannot create a file when that file already exists: './Mobius_Users/Mobius Bot4811_443058935784669194'

2018-11-02 17-22-03 - Mobius Bot sent to channel bot_testing : Error Caught On Command | Traceback (most recent call last):
  File "C:\Users\mwyoo\Google Drive\Michael's Documents\Misc\Coding Projects\Mobius System\Mobius - Dev\Bot\Mobiusbot.py", line 127, in on_message
    msg2=fn.register(usrobj)
  File "C:\Users\mwyoo\Google Drive\Michael's Documents\Misc\Coding Projects\Mobius System\Mobius - Dev\Bot\functions.py", line 162, in register
    os.makedirs(userinfo["folder"])
  File "C:\Users\mwyoo\AppData\Local\Programs\Python\Python36-32\lib\os.py", line 220, in makedirs
    mkdir(name, mode)
FileExistsError: [WinError 183] Cannot create a file when that file already exists: './Mobius_Users/Mobius Bot4811_443058935784669194'

2018-11-02 17-22-07 - Mobius Bot sent to channel bot_testing : Error Caught On Command | Traceback (most recent call last):
  File "C:\Users\mwyoo\Google Drive\Michael's Documents\Misc\Coding Projects\Mobius System\Mobius - Dev\Bot\Mobiusbot.py", line 127, in on_message
    msg2=fn.register(usrobj)
  File "C:\Users\mwyoo\Google Drive\Michael's Documents\Misc\Coding Projects\Mobius System\Mobius - Dev\Bot\functions.py", line 162, in register
    os.makedirs(userinfo["folder"])
  File "C:\Users\mwyoo\AppData\Local\Programs\Python\Python36-32\lib\os.py", line 220, in makedirs
    mkdir(name, mode)
FileExistsError: [WinError 183] Cannot create a file when that file already exists: './Mobius_Users/Mobius Bot4811_443058935784669194'

2018-11-02 17-22-07 - Mobius Bot sent to channel bot_testing : Error Caught On Command | Traceback (most recent call last):
  File "C:\Users\mwyoo\Google Drive\Michael's Documents\Misc\Coding Projects\Mobius System\Mobius - Dev\Bot\Mobiusbot.py", line 127, in on_message
    msg2=fn.register(usrobj)
  File "C:\Users\mwyoo\Google Drive\Michael's Documents\Misc\Coding Projects\Mobius System\Mobius - Dev\Bot\functions.py", line 162, in register
    os.makedirs(userinfo["folder"])
  File "C:\Users\mwyoo\AppData\Local\Programs\Python\Python36-32\lib\os.py", line 220, in makedirs
    mkdir(name, mode)
FileExistsError: [WinError 183] Cannot create a file when that file already exists: './Mobius_Users/Mobius Bot4811_443058935784669194'

2018-11-02 17-22-09 - Mobius Bot sent to channel bot_testing : Error Caught On Command | Traceback (most recent call last):
  File "C:\Users\mwyoo\Google Drive\Michael's Documents\Misc\Coding Projects\Mobius System\Mobius - Dev\Bot\Mobiusbot.py", line 127, in on_message
    msg2=fn.register(usrobj)
  File "C:\Users\mwyoo\Google Drive\Michael's Documents\Misc\Coding Projects\Mobius System\Mobius - Dev\Bot\functions.py", line 162, in register
    os.makedirs(userinfo["folder"])
  File "C:\Users\mwyoo\AppData\Local\Programs\Python\Python36-32\lib\os.py", line 220, in makedirs
    mkdir(name, mode)
FileExistsError: [WinError 183] Cannot create a file when that file already exists: './Mobius_Users/Mobius Bot4811_443058935784669194'

2018-11-02 17-22-09 - Mobius Bot sent to channel bot_testing : Error Caught On Command | Traceback (most recent call last):
  File "C:\Users\mwyoo\Google Drive\Michael's Documents\Misc\Coding Projects\Mobius System\Mobius - Dev\Bot\Mobiusbot.py", line 127, in on_message
    msg2=fn.register(usrobj)
  File "C:\Users\mwyoo\Google Drive\Michael's Documents\Misc\Coding Projects\Mobius System\Mobius - Dev\Bot\functions.py", line 162, in register
    os.makedirs(userinfo["folder"])
  File "C:\Users\mwyoo\AppData\Local\Programs\Python\Python36-32\lib\os.py", line 220, in makedirs
    mkdir(name, mode)
FileExistsError: [WinError 183] Cannot create a file when that file already exists: './Mobius_Users/Mobius Bot4811_443058935784669194'

2018-11-02 17-22-10 - Mobius Bot sent to channel bot_testing : Error Caught On Command | Traceback (most recent call last):
  File "C:\Users\mwyoo\Google Drive\Michael's Documents\Misc\Coding Projects\Mobius System\Mobius - Dev\Bot\Mobiusbot.py", line 127, in on_message
    msg2=fn.register(usrobj)
  File "C:\Users\mwyoo\Google Drive\Michael's Documents\Misc\Coding Projects\Mobius System\Mobius - Dev\Bot\functions.py", line 162, in register
    os.makedirs(userinfo["folder"])
  File "C:\Users\mwyoo\AppData\Local\Programs\Python\Python36-32\lib\os.py", line 220, in makedirs
    mkdir(name, mode)
FileExistsError: [WinError 183] Cannot create a file when that file already exists: './Mobius_Users/Mobius Bot4811_443058935784669194'

2018-11-02 17-22-13 - Mobius Bot sent to channel bot_testing : Error Caught On Command | Traceback (most recent call last):
  File "C:\Users\mwyoo\Google Drive\Michael's Documents\Misc\Coding Projects\Mobius System\Mobius - Dev\Bot\Mobiusbot.py", line 127, in on_message
    msg2=fn.register(usrobj)
  File "C:\Users\mwyoo\Google Drive\Michael's Documents\Misc\Coding Projects\Mobius System\Mobius - Dev\Bot\functions.py", line 162, in register
    os.makedirs(userinfo["folder"])
  File "C:\Users\mwyoo\AppData\Local\Programs\Python\Python36-32\lib\os.py", line 220, in makedirs
    mkdir(name, mode)
FileExistsError: [WinError 183] Cannot create a file when that file already exists: './Mobius_Users/Mobius Bot4811_443058935784669194'

2018-11-02 17-22-13 - Mobius Bot sent to channel bot_testing : Error Caught On Command | Traceback (most recent call last):
  File "C:\Users\mwyoo\Google Drive\Michael's Documents\Misc\Coding Projects\Mobius System\Mobius - Dev\Bot\Mobiusbot.py", line 127, in on_message
    msg2=fn.register(usrobj)
  File "C:\Users\mwyoo\Google Drive\Michael's Documents\Misc\Coding Projects\Mobius System\Mobius - Dev\Bot\functions.py", line 162, in register
    os.makedirs(userinfo["folder"])
  File "C:\Users\mwyoo\AppData\Local\Programs\Python\Python36-32\lib\os.py", line 220, in makedirs
    mkdir(name, mode)
FileExistsError: [WinError 183] Cannot create a file when that file already exists: './Mobius_Users/Mobius Bot4811_443058935784669194'

2018-11-02 17-22-15 - Mobius Bot sent to channel bot_testing : Error Caught On Command | Traceback (most recent call last):
  File "C:\Users\mwyoo\Google Drive\Michael's Documents\Misc\Coding Projects\Mobius System\Mobius - Dev\Bot\Mobiusbot.py", line 127, in on_message
    msg2=fn.register(usrobj)
  File "C:\Users\mwyoo\Google Drive\Michael's Documents\Misc\Coding Projects\Mobius System\Mobius - Dev\Bot\functions.py", line 162, in register
    os.makedirs(userinfo["folder"])
  File "C:\Users\mwyoo\AppData\Local\Programs\Python\Python36-32\lib\os.py", line 220, in makedirs
    mkdir(name, mode)
FileExistsError: [WinError 183] Cannot create a file when that file already exists: './Mobius_Users/Mobius Bot4811_443058935784669194'

2018-11-02 17-22-15 - Mobius Bot sent to channel bot_testing : Error Caught On Command | Traceback (most recent call last):
  File "C:\Users\mwyoo\Google Drive\Michael's Documents\Misc\Coding Projects\Mobius System\Mobius - Dev\Bot\Mobiusbot.py", line 127, in on_message
    msg2=fn.register(usrobj)
  File "C:\Users\mwyoo\Google Drive\Michael's Documents\Misc\Coding Projects\Mobius System\Mobius - Dev\Bot\functions.py", line 162, in register
    os.makedirs(userinfo["folder"])
  File "C:\Users\mwyoo\AppData\Local\Programs\Python\Python36-32\lib\os.py", line 220, in makedirs
    mkdir(name, mode)
FileExistsError: [WinError 183] Cannot create a file when that file already exists: './Mobius_Users/Mobius Bot4811_443058935784669194'

2018-11-02 17-22-15 - Mobius Bot sent to channel bot_testing : Error Caught On Command | Traceback (most recent call last):
  File "C:\Users\mwyoo\Google Drive\Michael's Documents\Misc\Coding Projects\Mobius System\Mobius - Dev\Bot\Mobiusbot.py", line 127, in on_message
    msg2=fn.register(usrobj)
  File "C:\Users\mwyoo\Google Drive\Michael's Documents\Misc\Coding Projects\Mobius System\Mobius - Dev\Bot\functions.py", line 162, in register
    os.makedirs(userinfo["folder"])
  File "C:\Users\mwyoo\AppData\Local\Programs\Python\Python36-32\lib\os.py", line 220, in makedirs
    mkdir(name, mode)
FileExistsError: [WinError 183] Cannot create a file when that file already exists: './Mobius_Users/Mobius Bot4811_443058935784669194'

2018-11-02 17-22-19 - Mobius Bot sent to channel bot_testing : Error Caught On Command | Traceback (most recent call last):
  File "C:\Users\mwyoo\Google Drive\Michael's Documents\Misc\Coding Projects\Mobius System\Mobius - Dev\Bot\Mobiusbot.py", line 127, in on_message
    msg2=fn.register(usrobj)
  File "C:\Users\mwyoo\Google Drive\Michael's Documents\Misc\Coding Projects\Mobius System\Mobius - Dev\Bot\functions.py", line 162, in register
    os.makedirs(userinfo["folder"])
  File "C:\Users\mwyoo\AppData\Local\Programs\Python\Python36-32\lib\os.py", line 220, in makedirs
    mkdir(name, mode)
FileExistsError: [WinError 183] Cannot create a file when that file already exists: './Mobius_Users/Mobius Bot4811_443058935784669194'

2018-11-02 17-22-19 - Mobius Bot sent to channel bot_testing : Error Caught On Command | Traceback (most recent call last):
  File "C:\Users\mwyoo\Google Drive\Michael's Documents\Misc\Coding Projects\Mobius System\Mobius - Dev\Bot\Mobiusbot.py", line 127, in on_message
    msg2=fn.register(usrobj)
  File "C:\Users\mwyoo\Google Drive\Michael's Documents\Misc\Coding Projects\Mobius System\Mobius - Dev\Bot\functions.py", line 162, in register
    os.makedirs(userinfo["folder"])
  File "C:\Users\mwyoo\AppData\Local\Programs\Python\Python36-32\lib\os.py", line 220, in makedirs
    mkdir(name, mode)
FileExistsError: [WinError 183] Cannot create a file when that file already exists: './Mobius_Users/Mobius Bot4811_443058935784669194'

2018-11-02 17-22-21 - Mobius Bot sent to channel bot_testing : Error Caught On Command | Traceback (most recent call last):
  File "C:\Users\mwyoo\Google Drive\Michael's Documents\Misc\Coding Projects\Mobius System\Mobius - Dev\Bot\Mobiusbot.py", line 127, in on_message
    msg2=fn.register(usrobj)
  File "C:\Users\mwyoo\Google Drive\Michael's Documents\Misc\Coding Projects\Mobius System\Mobius - Dev\Bot\functions.py", line 162, in register
    os.makedirs(userinfo["folder"])
  File "C:\Users\mwyoo\AppData\Local\Programs\Python\Python36-32\lib\os.py", line 220, in makedirs
    mkdir(name, mode)
FileExistsError: [WinError 183] Cannot create a file when that file already exists: './Mobius_Users/Mobius Bot4811_443058935784669194'

2018-11-02 17-22-21 - Mobius Bot sent to channel bot_testing : Error Caught On Command | Traceback (most recent call last):
  File "C:\Users\mwyoo\Google Drive\Michael's Documents\Misc\Coding Projects\Mobius System\Mobius - Dev\Bot\Mobiusbot.py", line 127, in on_message
    msg2=fn.register(usrobj)
  File "C:\Users\mwyoo\Google Drive\Michael's Documents\Misc\Coding Projects\Mobius System\Mobius - Dev\Bot\functions.py", line 162, in register
    os.makedirs(userinfo["folder"])
  File "C:\Users\mwyoo\AppData\Local\Programs\Python\Python36-32\lib\os.py", line 220, in makedirs
    mkdir(name, mode)
FileExistsError: [WinError 183] Cannot create a file when that file already exists: './Mobius_Users/Mobius Bot4811_443058935784669194'

2018-11-02 17-22-21 - Mobius Bot sent to channel bot_testing : Error Caught On Command | Traceback (most recent call last):
  File "C:\Users\mwyoo\Google Drive\Michael's Documents\Misc\Coding Projects\Mobius System\Mobius - Dev\Bot\Mobiusbot.py", line 127, in on_message
    msg2=fn.register(usrobj)
  File "C:\Users\mwyoo\Google Drive\Michael's Documents\Misc\Coding Projects\Mobius System\Mobius - Dev\Bot\functions.py", line 162, in register
    os.makedirs(userinfo["folder"])
  File "C:\Users\mwyoo\AppData\Local\Programs\Python\Python36-32\lib\os.py", line 220, in makedirs
    mkdir(name, mode)
FileExistsError: [WinError 183] Cannot create a file when that file already exists: './Mobius_Users/Mobius Bot4811_443058935784669194'

2018-11-02 17-22-25 - Mobius Bot sent to channel bot_testing : Error Caught On Command | Traceback (most recent call last):
  File "C:\Users\mwyoo\Google Drive\Michael's Documents\Misc\Coding Projects\Mobius System\Mobius - Dev\Bot\Mobiusbot.py", line 127, in on_message
    msg2=fn.register(usrobj)
  File "C:\Users\mwyoo\Google Drive\Michael's Documents\Misc\Coding Projects\Mobius System\Mobius - Dev\Bot\functions.py", line 162, in register
    os.makedirs(userinfo["folder"])
  File "C:\Users\mwyoo\AppData\Local\Programs\Python\Python36-32\lib\os.py", line 220, in makedirs
    mkdir(name, mode)
FileExistsError: [WinError 183] Cannot create a file when that file already exists: './Mobius_Users/Mobius Bot4811_443058935784669194'

2018-11-02 17-22-25 - Mobius Bot sent to channel bot_testing : Error Caught On Command | Traceback (most recent call last):
  File "C:\Users\mwyoo\Google Drive\Michael's Documents\Misc\Coding Projects\Mobius System\Mobius - Dev\Bot\Mobiusbot.py", line 127, in on_message
    msg2=fn.register(usrobj)
  File "C:\Users\mwyoo\Google Drive\Michael's Documents\Misc\Coding Projects\Mobius System\Mobius - Dev\Bot\functions.py", line 162, in register
    os.makedirs(userinfo["folder"])
  File "C:\Users\mwyoo\AppData\Local\Programs\Python\Python36-32\lib\os.py", line 220, in makedirs
    mkdir(name, mode)
FileExistsError: [WinError 183] Cannot create a file when that file already exists: './Mobius_Users/Mobius Bot4811_443058935784669194'

2018-11-02 17-22-27 - Mobius Bot sent to channel bot_testing : Error Caught On Command | Traceback (most recent call last):
  File "C:\Users\mwyoo\Google Drive\Michael's Documents\Misc\Coding Projects\Mobius System\Mobius - Dev\Bot\Mobiusbot.py", line 127, in on_message
    msg2=fn.register(usrobj)
  File "C:\Users\mwyoo\Google Drive\Michael's Documents\Misc\Coding Projects\Mobius System\Mobius - Dev\Bot\functions.py", line 162, in register
    os.makedirs(userinfo["folder"])
  File "C:\Users\mwyoo\AppData\Local\Programs\Python\Python36-32\lib\os.py", line 220, in makedirs
    mkdir(name, mode)
FileExistsError: [WinError 183] Cannot create a file when that file already exists: './Mobius_Users/Mobius Bot4811_443058935784669194'

2018-11-02 17-22-27 - Mobius Bot sent to channel bot_testing : Error Caught On Command | Traceback (most recent call last):
  File "C:\Users\mwyoo\Google Drive\Michael's Documents\Misc\Coding Projects\Mobius System\Mobius - Dev\Bot\Mobiusbot.py", line 127, in on_message
    msg2=fn.register(usrobj)
  File "C:\Users\mwyoo\Google Drive\Michael's Documents\Misc\Coding Projects\Mobius System\Mobius - Dev\Bot\functions.py", line 162, in register
    os.makedirs(userinfo["folder"])
  File "C:\Users\mwyoo\AppData\Local\Programs\Python\Python36-32\lib\os.py", line 220, in makedirs
    mkdir(name, mode)
FileExistsError: [WinError 183] Cannot create a file when that file already exists: './Mobius_Users/Mobius Bot4811_443058935784669194'

2018-11-02 17-22-27 - Mobius Bot sent to channel bot_testing : Error Caught On Command | Traceback (most recent call last):
  File "C:\Users\mwyoo\Google Drive\Michael's Documents\Misc\Coding Projects\Mobius System\Mobius - Dev\Bot\Mobiusbot.py", line 127, in on_message
    msg2=fn.register(usrobj)
  File "C:\Users\mwyoo\Google Drive\Michael's Documents\Misc\Coding Projects\Mobius System\Mobius - Dev\Bot\functions.py", line 162, in register
    os.makedirs(userinfo["folder"])
  File "C:\Users\mwyoo\AppData\Local\Programs\Python\Python36-32\lib\os.py", line 220, in makedirs
    mkdir(name, mode)
FileExistsError: [WinError 183] Cannot create a file when that file already exists: './Mobius_Users/Mobius Bot4811_443058935784669194'

2018-11-02 17-22-31 - Mobius Bot sent to channel bot_testing : Error Caught On Command | Traceback (most recent call last):
  File "C:\Users\mwyoo\Google Drive\Michael's Documents\Misc\Coding Projects\Mobius System\Mobius - Dev\Bot\Mobiusbot.py", line 127, in on_message
    msg2=fn.register(usrobj)
  File "C:\Users\mwyoo\Google Drive\Michael's Documents\Misc\Coding Projects\Mobius System\Mobius - Dev\Bot\functions.py", line 162, in register
    os.makedirs(userinfo["folder"])
  File "C:\Users\mwyoo\AppData\Local\Programs\Python\Python36-32\lib\os.py", line 220, in makedirs
    mkdir(name, mode)
FileExistsError: [WinError 183] Cannot create a file when that file already exists: './Mobius_Users/Mobius Bot4811_443058935784669194'

2018-11-02 17-22-31 - Mobius Bot sent to channel bot_testing : Error Caught On Command | Traceback (most recent call last):
  File "C:\Users\mwyoo\Google Drive\Michael's Documents\Misc\Coding Projects\Mobius System\Mobius - Dev\Bot\Mobiusbot.py", line 127, in on_message
    msg2=fn.register(usrobj)
  File "C:\Users\mwyoo\Google Drive\Michael's Documents\Misc\Coding Projects\Mobius System\Mobius - Dev\Bot\functions.py", line 162, in register
    os.makedirs(userinfo["folder"])
  File "C:\Users\mwyoo\AppData\Local\Programs\Python\Python36-32\lib\os.py", line 220, in makedirs
    mkdir(name, mode)
FileExistsError: [WinError 183] Cannot create a file when that file already exists: './Mobius_Users/Mobius Bot4811_443058935784669194'

2018-11-02 17-22-33 - Mobius Bot sent to channel bot_testing : Error Caught On Command | Traceback (most recent call last):
  File "C:\Users\mwyoo\Google Drive\Michael's Documents\Misc\Coding Projects\Mobius System\Mobius - Dev\Bot\Mobiusbot.py", line 127, in on_message
    msg2=fn.register(usrobj)
  File "C:\Users\mwyoo\Google Drive\Michael's Documents\Misc\Coding Projects\Mobius System\Mobius - Dev\Bot\functions.py", line 162, in register
    os.makedirs(userinfo["folder"])
  File "C:\Users\mwyoo\AppData\Local\Programs\Python\Python36-32\lib\os.py", line 220, in makedirs
    mkdir(name, mode)
FileExistsError: [WinError 183] Cannot create a file when that file already exists: './Mobius_Users/Mobius Bot4811_443058935784669194'

2018-11-02 17-22-33 - Mobius Bot sent to channel bot_testing : Error Caught On Command | Traceback (most recent call last):
  File "C:\Users\mwyoo\Google Drive\Michael's Documents\Misc\Coding Projects\Mobius System\Mobius - Dev\Bot\Mobiusbot.py", line 127, in on_message
    msg2=fn.register(usrobj)
  File "C:\Users\mwyoo\Google Drive\Michael's Documents\Misc\Coding Projects\Mobius System\Mobius - Dev\Bot\functions.py", line 162, in register
    os.makedirs(userinfo["folder"])
  File "C:\Users\mwyoo\AppData\Local\Programs\Python\Python36-32\lib\os.py", line 220, in makedirs
    mkdir(name, mode)
FileExistsError: [WinError 183] Cannot create a file when that file already exists: './Mobius_Users/Mobius Bot4811_443058935784669194'

2018-11-02 17-22-33 - Mobius Bot sent to channel bot_testing : Error Caught On Command | Traceback (most recent call last):
  File "C:\Users\mwyoo\Google Drive\Michael's Documents\Misc\Coding Projects\Mobius System\Mobius - Dev\Bot\Mobiusbot.py", line 127, in on_message
    msg2=fn.register(usrobj)
  File "C:\Users\mwyoo\Google Drive\Michael's Documents\Misc\Coding Projects\Mobius System\Mobius - Dev\Bot\functions.py", line 162, in register
    os.makedirs(userinfo["folder"])
  File "C:\Users\mwyoo\AppData\Local\Programs\Python\Python36-32\lib\os.py", line 220, in makedirs
    mkdir(name, mode)
FileExistsError: [WinError 183] Cannot create a file when that file already exists: './Mobius_Users/Mobius Bot4811_443058935784669194'

2018-11-02 17-22-37 - Mobius Bot sent to channel bot_testing : Error Caught On Command | Traceback (most recent call last):
  File "C:\Users\mwyoo\Google Drive\Michael's Documents\Misc\Coding Projects\Mobius System\Mobius - Dev\Bot\Mobiusbot.py", line 127, in on_message
    msg2=fn.register(usrobj)
  File "C:\Users\mwyoo\Google Drive\Michael's Documents\Misc\Coding Projects\Mobius System\Mobius - Dev\Bot\functions.py", line 162, in register
    os.makedirs(userinfo["folder"])
  File "C:\Users\mwyoo\AppData\Local\Programs\Python\Python36-32\lib\os.py", line 220, in makedirs
    mkdir(name, mode)
FileExistsError: [WinError 183] Cannot create a file when that file already exists: './Mobius_Users/Mobius Bot4811_443058935784669194'

2018-11-02 17-22-37 - Mobius Bot sent to channel bot_testing : Error Caught On Command | Traceback (most recent call last):
  File "C:\Users\mwyoo\Google Drive\Michael's Documents\Misc\Coding Projects\Mobius System\Mobius - Dev\Bot\Mobiusbot.py", line 127, in on_message
    msg2=fn.register(usrobj)
  File "C:\Users\mwyoo\Google Drive\Michael's Documents\Misc\Coding Projects\Mobius System\Mobius - Dev\Bot\functions.py", line 162, in register
    os.makedirs(userinfo["folder"])
  File "C:\Users\mwyoo\AppData\Local\Programs\Python\Python36-32\lib\os.py", line 220, in makedirs
    mkdir(name, mode)
FileExistsError: [WinError 183] Cannot create a file when that file already exists: './Mobius_Users/Mobius Bot4811_443058935784669194'

2018-11-02 17-22-39 - Mobius Bot sent to channel bot_testing : Error Caught On Command | Traceback (most recent call last):
  File "C:\Users\mwyoo\Google Drive\Michael's Documents\Misc\Coding Projects\Mobius System\Mobius - Dev\Bot\Mobiusbot.py", line 127, in on_message
    msg2=fn.register(usrobj)
  File "C:\Users\mwyoo\Google Drive\Michael's Documents\Misc\Coding Projects\Mobius System\Mobius - Dev\Bot\functions.py", line 162, in register
    os.makedirs(userinfo["folder"])
  File "C:\Users\mwyoo\AppData\Local\Programs\Python\Python36-32\lib\os.py", line 220, in makedirs
    mkdir(name, mode)
FileExistsError: [WinError 183] Cannot create a file when that file already exists: './Mobius_Users/Mobius Bot4811_443058935784669194'

2018-11-02 17-22-39 - Mobius Bot sent to channel bot_testing : Error Caught On Command | Traceback (most recent call last):
  File "C:\Users\mwyoo\Google Drive\Michael's Documents\Misc\Coding Projects\Mobius System\Mobius - Dev\Bot\Mobiusbot.py", line 127, in on_message
    msg2=fn.register(usrobj)
  File "C:\Users\mwyoo\Google Drive\Michael's Documents\Misc\Coding Projects\Mobius System\Mobius - Dev\Bot\functions.py", line 162, in register
    os.makedirs(userinfo["folder"])
  File "C:\Users\mwyoo\AppData\Local\Programs\Python\Python36-32\lib\os.py", line 220, in makedirs
    mkdir(name, mode)
FileExistsError: [WinError 183] Cannot create a file when that file already exists: './Mobius_Users/Mobius Bot4811_443058935784669194'

2018-11-02 17-22-39 - Mobius Bot sent to channel bot_testing : Error Caught On Command | Traceback (most recent call last):
  File "C:\Users\mwyoo\Google Drive\Michael's Documents\Misc\Coding Projects\Mobius System\Mobius - Dev\Bot\Mobiusbot.py", line 127, in on_message
    msg2=fn.register(usrobj)
  File "C:\Users\mwyoo\Google Drive\Michael's Documents\Misc\Coding Projects\Mobius System\Mobius - Dev\Bot\functions.py", line 162, in register
    os.makedirs(userinfo["folder"])
  File "C:\Users\mwyoo\AppData\Local\Programs\Python\Python36-32\lib\os.py", line 220, in makedirs
    mkdir(name, mode)
FileExistsError: [WinError 183] Cannot create a file when that file already exists: './Mobius_Users/Mobius Bot4811_443058935784669194'

2018-11-02 17-22-43 - Mobius Bot sent to channel bot_testing : Error Caught On Command | Traceback (most recent call last):
  File "C:\Users\mwyoo\Google Drive\Michael's Documents\Misc\Coding Projects\Mobius System\Mobius - Dev\Bot\Mobiusbot.py", line 127, in on_message
    msg2=fn.register(usrobj)
  File "C:\Users\mwyoo\Google Drive\Michael's Documents\Misc\Coding Projects\Mobius System\Mobius - Dev\Bot\functions.py", line 162, in register
    os.makedirs(userinfo["folder"])
  File "C:\Users\mwyoo\AppData\Local\Programs\Python\Python36-32\lib\os.py", line 220, in makedirs
    mkdir(name, mode)
FileExistsError: [WinError 183] Cannot create a file when that file already exists: './Mobius_Users/Mobius Bot4811_443058935784669194'

2018-11-02 17-22-43 - Mobius Bot sent to channel bot_testing : Error Caught On Command | Traceback (most recent call last):
  File "C:\Users\mwyoo\Google Drive\Michael's Documents\Misc\Coding Projects\Mobius System\Mobius - Dev\Bot\Mobiusbot.py", line 127, in on_message
    msg2=fn.register(usrobj)
  File "C:\Users\mwyoo\Google Drive\Michael's Documents\Misc\Coding Projects\Mobius System\Mobius - Dev\Bot\functions.py", line 162, in register
    os.makedirs(userinfo["folder"])
  File "C:\Users\mwyoo\AppData\Local\Programs\Python\Python36-32\lib\os.py", line 220, in makedirs
    mkdir(name, mode)
FileExistsError: [WinError 183] Cannot create a file when that file already exists: './Mobius_Users/Mobius Bot4811_443058935784669194'

2018-11-02 17-22-45 - Mobius Bot sent to channel bot_testing : Error Caught On Command | Traceback (most recent call last):
  File "C:\Users\mwyoo\Google Drive\Michael's Documents\Misc\Coding Projects\Mobius System\Mobius - Dev\Bot\Mobiusbot.py", line 127, in on_message
    msg2=fn.register(usrobj)
  File "C:\Users\mwyoo\Google Drive\Michael's Documents\Misc\Coding Projects\Mobius System\Mobius - Dev\Bot\functions.py", line 162, in register
    os.makedirs(userinfo["folder"])
  File "C:\Users\mwyoo\AppData\Local\Programs\Python\Python36-32\lib\os.py", line 220, in makedirs
    mkdir(name, mode)
FileExistsError: [WinError 183] Cannot create a file when that file already exists: './Mobius_Users/Mobius Bot4811_443058935784669194'

2018-11-02 17-22-46 - Mobius Bot sent to channel bot_testing : Error Caught On Command | Traceback (most recent call last):
  File "C:\Users\mwyoo\Google Drive\Michael's Documents\Misc\Coding Projects\Mobius System\Mobius - Dev\Bot\Mobiusbot.py", line 127, in on_message
    msg2=fn.register(usrobj)
  File "C:\Users\mwyoo\Google Drive\Michael's Documents\Misc\Coding Projects\Mobius System\Mobius - Dev\Bot\functions.py", line 162, in register
    os.makedirs(userinfo["folder"])
  File "C:\Users\mwyoo\AppData\Local\Programs\Python\Python36-32\lib\os.py", line 220, in makedirs
    mkdir(name, mode)
FileExistsError: [WinError 183] Cannot create a file when that file already exists: './Mobius_Users/Mobius Bot4811_443058935784669194'

2018-11-02 17-22-46 - Mobius Bot sent to channel bot_testing : Error Caught On Command | Traceback (most recent call last):
  File "C:\Users\mwyoo\Google Drive\Michael's Documents\Misc\Coding Projects\Mobius System\Mobius - Dev\Bot\Mobiusbot.py", line 127, in on_message
    msg2=fn.register(usrobj)
  File "C:\Users\mwyoo\Google Drive\Michael's Documents\Misc\Coding Projects\Mobius System\Mobius - Dev\Bot\functions.py", line 162, in register
    os.makedirs(userinfo["folder"])
  File "C:\Users\mwyoo\AppData\Local\Programs\Python\Python36-32\lib\os.py", line 220, in makedirs
    mkdir(name, mode)
FileExistsError: [WinError 183] Cannot create a file when that file already exists: './Mobius_Users/Mobius Bot4811_443058935784669194'

2018-11-02 17-22-49 - Mobius Bot sent to channel bot_testing : Error Caught On Command | Traceback (most recent call last):
  File "C:\Users\mwyoo\Google Drive\Michael's Documents\Misc\Coding Projects\Mobius System\Mobius - Dev\Bot\Mobiusbot.py", line 127, in on_message
    msg2=fn.register(usrobj)
  File "C:\Users\mwyoo\Google Drive\Michael's Documents\Misc\Coding Projects\Mobius System\Mobius - Dev\Bot\functions.py", line 162, in register
    os.makedirs(userinfo["folder"])
  File "C:\Users\mwyoo\AppData\Local\Programs\Python\Python36-32\lib\os.py", line 220, in makedirs
    mkdir(name, mode)
FileExistsError: [WinError 183] Cannot create a file when that file already exists: './Mobius_Users/Mobius Bot4811_443058935784669194'

2018-11-02 17-22-49 - Mobius Bot sent to channel bot_testing : Error Caught On Command | Traceback (most recent call last):
  File "C:\Users\mwyoo\Google Drive\Michael's Documents\Misc\Coding Projects\Mobius System\Mobius - Dev\Bot\Mobiusbot.py", line 127, in on_message
    msg2=fn.register(usrobj)
  File "C:\Users\mwyoo\Google Drive\Michael's Documents\Misc\Coding Projects\Mobius System\Mobius - Dev\Bot\functions.py", line 162, in register
    os.makedirs(userinfo["folder"])
  File "C:\Users\mwyoo\AppData\Local\Programs\Python\Python36-32\lib\os.py", line 220, in makedirs
    mkdir(name, mode)
FileExistsError: [WinError 183] Cannot create a file when that file already exists: './Mobius_Users/Mobius Bot4811_443058935784669194'

2018-11-02 17-22-51 - Mobius Bot sent to channel bot_testing : Error Caught On Command | Traceback (most recent call last):
  File "C:\Users\mwyoo\Google Drive\Michael's Documents\Misc\Coding Projects\Mobius System\Mobius - Dev\Bot\Mobiusbot.py", line 127, in on_message
    msg2=fn.register(usrobj)
  File "C:\Users\mwyoo\Google Drive\Michael's Documents\Misc\Coding Projects\Mobius System\Mobius - Dev\Bot\functions.py", line 162, in register
    os.makedirs(userinfo["folder"])
  File "C:\Users\mwyoo\AppData\Local\Programs\Python\Python36-32\lib\os.py", line 220, in makedirs
    mkdir(name, mode)
FileExistsError: [WinError 183] Cannot create a file when that file already exists: './Mobius_Users/Mobius Bot4811_443058935784669194'

2018-11-02 17-22-51 - Mobius Bot sent to channel bot_testing : Error Caught On Command | Traceback (most recent call last):
  File "C:\Users\mwyoo\Google Drive\Michael's Documents\Misc\Coding Projects\Mobius System\Mobius - Dev\Bot\Mobiusbot.py", line 127, in on_message
    msg2=fn.register(usrobj)
  File "C:\Users\mwyoo\Google Drive\Michael's Documents\Misc\Coding Projects\Mobius System\Mobius - Dev\Bot\functions.py", line 162, in register
    os.makedirs(userinfo["folder"])
  File "C:\Users\mwyoo\AppData\Local\Programs\Python\Python36-32\lib\os.py", line 220, in makedirs
    mkdir(name, mode)
FileExistsError: [WinError 183] Cannot create a file when that file already exists: './Mobius_Users/Mobius Bot4811_443058935784669194'

2018-11-02 17-22-52 - Mobius Bot sent to channel bot_testing : Error Caught On Command | Traceback (most recent call last):
  File "C:\Users\mwyoo\Google Drive\Michael's Documents\Misc\Coding Projects\Mobius System\Mobius - Dev\Bot\Mobiusbot.py", line 127, in on_message
    msg2=fn.register(usrobj)
  File "C:\Users\mwyoo\Google Drive\Michael's Documents\Misc\Coding Projects\Mobius System\Mobius - Dev\Bot\functions.py", line 162, in register
    os.makedirs(userinfo["folder"])
  File "C:\Users\mwyoo\AppData\Local\Programs\Python\Python36-32\lib\os.py", line 220, in makedirs
    mkdir(name, mode)
FileExistsError: [WinError 183] Cannot create a file when that file already exists: './Mobius_Users/Mobius Bot4811_443058935784669194'

2018-11-02 17-22-55 - Mobius Bot sent to channel bot_testing : Error Caught On Command | Traceback (most recent call last):
  File "C:\Users\mwyoo\Google Drive\Michael's Documents\Misc\Coding Projects\Mobius System\Mobius - Dev\Bot\Mobiusbot.py", line 127, in on_message
    msg2=fn.register(usrobj)
  File "C:\Users\mwyoo\Google Drive\Michael's Documents\Misc\Coding Projects\Mobius System\Mobius - Dev\Bot\functions.py", line 162, in register
    os.makedirs(userinfo["folder"])
  File "C:\Users\mwyoo\AppData\Local\Programs\Python\Python36-32\lib\os.py", line 220, in makedirs
    mkdir(name, mode)
FileExistsError: [WinError 183] Cannot create a file when that file already exists: './Mobius_Users/Mobius Bot4811_443058935784669194'

2018-11-02 17-22-55 - Mobius Bot sent to channel bot_testing : Error Caught On Command | Traceback (most recent call last):
  File "C:\Users\mwyoo\Google Drive\Michael's Documents\Misc\Coding Projects\Mobius System\Mobius - Dev\Bot\Mobiusbot.py", line 127, in on_message
    msg2=fn.register(usrobj)
  File "C:\Users\mwyoo\Google Drive\Michael's Documents\Misc\Coding Projects\Mobius System\Mobius - Dev\Bot\functions.py", line 162, in register
    os.makedirs(userinfo["folder"])
  File "C:\Users\mwyoo\AppData\Local\Programs\Python\Python36-32\lib\os.py", line 220, in makedirs
    mkdir(name, mode)
FileExistsError: [WinError 183] Cannot create a file when that file already exists: './Mobius_Users/Mobius Bot4811_443058935784669194'

2018-11-02 18-48-11 - Cucoo5 sent to channel bot_testing : <<badcmd | Traceback (most recent call last):
  File "C:\Users\mwyoo\Google Drive\Michael's Documents\Misc\Coding Projects\Mobius System\Mobius - Dev\Bot\Mobiusbot.py", line 128, in on_message
    output = stdby_app.in_and_out(message)
  File "C:\Users\mwyoo\Google Drive\Michael's Documents\Misc\Coding Projects\Mobius System\Mobius - Dev\Apps\standby\basic_cmds.py", line 89, in in_and_out
    msg=self.__badcmd()
  File "C:\Users\mwyoo\Google Drive\Michael's Documents\Misc\Coding Projects\Mobius System\Mobius - Dev\Apps\standby\basic_cmds.py", line 210, in __badcmd
    raise ValueError("Error testing")
ValueError: Error testing

2018-11-02 18-49-34 - Cucoo5 sent to channel bot_testing : <<register | Traceback (most recent call last):
  File "C:\Users\mwyoo\Google Drive\Michael's Documents\Misc\Coding Projects\Mobius System\Mobius - Dev\Bot\Mobiusbot.py", line 128, in on_message
    output = stdby_app.in_and_out(message)
  File "C:\Users\mwyoo\Google Drive\Michael's Documents\Misc\Coding Projects\Mobius System\Mobius - Dev\Apps\standby\basic_cmds.py", line 109, in in_and_out
    msg,cmd=self.__registercmd()
  File "C:\Users\mwyoo\Google Drive\Michael's Documents\Misc\Coding Projects\Mobius System\Mobius - Dev\Apps\standby\basic_cmds.py", line 255, in __registercmd
    msg=register(self.usr)
NameError: name 'register' is not defined

2018-11-02 18-49-47 - Snowyvaan sent to channel bot_testing : <<register | Traceback (most recent call last):
  File "C:\Users\mwyoo\Google Drive\Michael's Documents\Misc\Coding Projects\Mobius System\Mobius - Dev\Bot\Mobiusbot.py", line 128, in on_message
    output = stdby_app.in_and_out(message)
  File "C:\Users\mwyoo\Google Drive\Michael's Documents\Misc\Coding Projects\Mobius System\Mobius - Dev\Apps\standby\basic_cmds.py", line 109, in in_and_out
    msg,cmd=self.__registercmd()
  File "C:\Users\mwyoo\Google Drive\Michael's Documents\Misc\Coding Projects\Mobius System\Mobius - Dev\Apps\standby\basic_cmds.py", line 255, in __registercmd
    msg=register(self.usr)
NameError: name 'register' is not defined

2018-11-02 19-03-53 - Cucoo5 sent to channel bot_testing : <<register | Traceback (most recent call last):
  File "C:\Users\mwyoo\Google Drive\Michael's Documents\Misc\Coding Projects\Mobius System\Mobius - Dev\Bot\Mobiusbot.py", line 134, in on_message
    for output in outputhandler(output,usrobj):
  File "C:\Users\mwyoo\Google Drive\Michael's Documents\Misc\Coding Projects\Mobius System\Mobius - Dev\Bot\Mobiusbot.py", line 106, in outputhandler
    outsys.append(client.send_message(usrobj, msg))
NameError: name 'usrobj' is not defined

2018-11-02 19-04-44 - Cucoo5 sent to channel bot_testing : <<register | Traceback (most recent call last):
  File "C:\Users\mwyoo\Google Drive\Michael's Documents\Misc\Coding Projects\Mobius System\Mobius - Dev\Bot\Mobiusbot.py", line 134, in on_message
    for output in outputhandler(output,usrobj):
  File "C:\Users\mwyoo\Google Drive\Michael's Documents\Misc\Coding Projects\Mobius System\Mobius - Dev\Bot\Mobiusbot.py", line 106, in outputhandler
    outsys.append(client.send_message(usrobj, msg))
NameError: name 'usrobj' is not defined

